<?xml version="1.0" ?>
<robot name="my_robot">

  <link name="base_link">
    <visual>
      <geometry><box size="0.4 0.3 0.1"/></geometry>
      <material name="blue"><color rgba="0 0 1 1"/></material>
    </visual>
    <collision>
      <geometry><box size="0.4 0.28 0.1"/></geometry>
    </collision>
    <inertial>
      <mass value="5.0"/>
      <inertia ixx="0.04" ixy="0" ixz="0" iyy="0.07" iyz="0" izz="0.1"/>
    </inertial>
  </link>

  <link name="left_wheel">
    <visual><geometry><cylinder radius="0.1" length="0.05"/></geometry></visual>
    <collision><geometry><cylinder radius="0.1" length="0.05"/></geometry></collision>
    <inertial><mass value="1.0"/><inertia ixx="0.003" ixy="0" ixz="0" iyy="0.003" iyz="0" izz="0.005"/></inertial>
  </link>
  <joint name="left_joint" type="continuous">
    <parent link="base_link"/><child link="left_wheel"/>
    <origin xyz="0 0.175 0" rpy="-1.5708 0 0"/><axis xyz="0 0 1"/>
  </joint>

  <link name="right_wheel">
    <visual><geometry><cylinder radius="0.1" length="0.05"/></geometry></visual>
    <collision><geometry><cylinder radius="0.1" length="0.05"/></geometry></collision>
    <inertial><mass value="1.0"/><inertia ixx="0.003" ixy="0" ixz="0" iyy="0.003" iyz="0" izz="0.005"/></inertial>
  </link>
  <joint name="right_joint" type="continuous">
    <parent link="base_link"/><child link="right_wheel"/>
    <origin xyz="0 -0.175 0" rpy="-1.5708 0 0"/><axis xyz="0 0 1"/>
  </joint>

  <link name="front_caster">
    <visual>
      <geometry><sphere radius="0.05"/></geometry>
      <material name="grey"><color rgba="0.5 0.5 0.5 1"/></material>
    </visual>
    <collision><geometry><sphere radius="0.05"/></geometry></collision>
    <inertial><mass value="0.5"/><inertia ixx="0.001" ixy="0" ixz="0" iyy="0.001" iyz="0" izz="0.001"/></inertial>
  </link>
  <joint name="front_caster_joint" type="fixed">
    <parent link="base_link"/><child link="front_caster"/>
    <origin xyz="0.15 0 -0.05" rpy="0 0 0"/>
  </joint>

  <link name="rear_caster">
    <visual><geometry><sphere radius="0.05"/></geometry><material name="grey"><color rgba="0.5 0.5 0.5 1"/></material></visual>
    <collision><geometry><sphere radius="0.05"/></geometry></collision>
    <inertial><mass value="0.5"/><inertia ixx="0.001" ixy="0" ixz="0" iyy="0.001" iyz="0" izz="0.001"/></inertial>
  </link>
  <joint name="rear_caster_joint" type="fixed">
    <parent link="base_link"/><child link="rear_caster"/>
    <origin xyz="-0.15 0 -0.05" rpy="0 0 0"/>
  </joint>

  <gazebo reference="front_caster">
    <mu1>0.0</mu1>
    <mu2>0.0</mu2>
  </gazebo>
  <gazebo reference="rear_caster">
    <mu1>0.0</mu1>
    <mu2>0.0</mu2>
  </gazebo>

  <link name="laser">
    <visual><geometry><cylinder radius="0.05" length="0.05"/></geometry><material name="red"><color rgba="1 0 0 1"/></material></visual>
    <collision><geometry><cylinder radius="0.05" length="0.05"/></geometry></collision>
    <inertial><mass value="0.2"/><inertia ixx="0.001" ixy="0" ixz="0" iyy="0.001" iyz="0" izz="0.001"/></inertial>
  </link>
  <joint name="laser_joint" type="fixed">
    <parent link="base_link"/><child link="laser"/>
    <origin xyz="0 0 0.2" rpy="0 0 0"/>
  </joint>

  <gazebo>
    <plugin filename="gz-sim-diff-drive-system" name="gz::sim::systems::DiffDrive">
      <left_joint>left_joint</left_joint>
      <right_joint>right_joint</right_joint>
      
      <wheel_separation>0.35</wheel_separation>
      <wheel_radius>0.1</wheel_radius>
      
      <odom_publish_frequency>50</odom_publish_frequency>
      <topic>/cmd_vel</topic>
      <odom_topic>/odom</odom_topic>
      <tf_topic>/tf</tf_topic>
      <frame_id>odom</frame_id>
      <child_frame_id>base_link</child_frame_id>
    </plugin>
  </gazebo>

  <gazebo reference="laser">
    <sensor name="laser_sensor" type="gpu_lidar">
      <topic>/scan</topic>
      <update_rate>10</update_rate>
      <gz_frame_id>laser</gz_frame_id>
      <lidar>
        <scan>
          <horizontal>
            <samples>360</samples>
            <resolution>1</resolution>
            <min_angle>-3.14159</min_angle>
            <max_angle>3.14159</max_angle>
          </horizontal>
        </scan>
        <range><min>0.35</min><max>12.0</max></range>
      </lidar>
      <always_on>1</always_on>
      <visualize>true</visualize>
    </sensor>
  </gazebo>
</robot>